Workbook

Sheet Mid Carrier
A1: Breakout Header (J14)
A2: Pin_x000D_ number | B2: Function | C2: Portenta X8_x000D_ (Linux) | D2: Portenta X8_x000D_ (Python® - Modes:_x000D_ BOARD / BCM / IMX / X8) | E2: Portenta X8_x000D_ (Arduino) | F2: Portenta H7 | G2: H7 pin number | H2: Portenta C33
A3: 3 | B3: SERIAL0 RTS | C3: 181 | D3: 3 / - / 181 / RTS0 | E3: PC_7 | F3: PI_1 | G3: =_xlfn.XLOOKUP(F3, pin_name_table!$A$2:$A$171,pin_name_table!$B$2:$B$171,"") -> 9 | H3: 51
A4: 4 | B4: SERIAL1 RTS | C4: 126 | D4: 4 / - / 126 / RTS1 | E4: - | F4: PI_14 | G4: =_xlfn.XLOOKUP(F4, pin_name_table!$A$2:$A$171,pin_name_table!$B$2:$B$171,"") -> 71 | H4: 61
A5: 7 | B5: SERIAL0 RX | C5: 180 | D5: 7 / - / 180 / RX0 | E5: - | F5: PI_9 | G5: =_xlfn.XLOOKUP(F5, pin_name_table!$A$2:$A$171,pin_name_table!$B$2:$B$171,"") -> 68 | H5: 50
A6: 8 | B6: SERIAL1 RX | C6: 127 | D6: 8 / - / 127 / RX1 | E6: PE_11 | F6: PA_10 | G6: =_xlfn.XLOOKUP(F6, pin_name_table!$A$2:$A$171,pin_name_table!$B$2:$B$171,"") -> 13 | H6: 13
A7: 9 | B7: SERIAL0 TX | C7: 179 | D7: 9 / - / 179 / TX0 | E7: - | F7: PA_0 | G7: =_xlfn.XLOOKUP(F7, pin_name_table!$A$2:$A$171,pin_name_table!$B$2:$B$171,"") -> 27 | H7: 49
A8: 10 | B8: SERIAL1 TX | C8: 128 | D8: 10 / - / 128 / TX1 | E8: - | F8: PA_9 | G8: =_xlfn.XLOOKUP(F8, pin_name_table!$A$2:$A$171,pin_name_table!$B$2:$B$171,"") -> 14 | H8: 14
A9: 11 | B9: SERIAL0 CTS | C9: 182 | D9: 11 / - / 182 / CTS0 | E9: - | F9: PI_13 | G9: =_xlfn.XLOOKUP(F9, pin_name_table!$A$2:$A$171,pin_name_table!$B$2:$B$171,"") -> 70 | H9: 52
A10: 12 | B10: SERIAL1 CTS | C10: 125 | D10: 12 / - / 125 / CTS1 | E10: - | F10: PI_15 | G10: =_xlfn.XLOOKUP(F10, pin_name_table!$A$2:$A$171,pin_name_table!$B$2:$B$171,"") -> 72 | H10: 62
A11: 15 | B11: SERIAL2 RTS | C11: NC | D11: 15 / - / - / RTS2 | E11: - | F11: - | G11: =_xlfn.XLOOKUP(F11, pin_name_table!$A$2:$A$171,pin_name_table!$B$2:$B$171,"") | H11: 51
A12: 16 | B12: SERIAL3 RTS | C12: NC | D12: 16 / - / - / RTS3 | E12: - | F12: - | G12: =_xlfn.XLOOKUP(F12, pin_name_table!$A$2:$A$171,pin_name_table!$B$2:$B$171,"") | H12: 55
A13: 19 | B13: SERIAL2 RX | C13: 154 | D13: 19 / - / 154 / RX2 | E13: - | F13: PG_9 | G13: =_xlfn.XLOOKUP(F13, pin_name_table!$A$2:$A$171,pin_name_table!$B$2:$B$171,"") -> 51 | H13: 50
A14: 20 | B14: SERIAL3 RX | C14: 156 | D14: 20 / - / 156 / RX3 | E14: - | F14: PJ_9 | G14: =_xlfn.XLOOKUP(F14, pin_name_table!$A$2:$A$171,pin_name_table!$B$2:$B$171,"") -> 76 | H14: 54
... A26: 32 | B26: CAN1 RX | C26: 178 | D26: 32 / - / 178 / CAN1_RX | E26: - | F26: PB_8 | G26: =_xlfn.XLOOKUP(F26, pin_name_table!$A$2:$A$171,pin_name_table!$B$2:$B$171,"") -> 37 | H26: 43
A27: 33 | B27: SPDIF TX | C27: 131 | D27: 33 / - / 131 / SPDIF_TX | E27: - | F27: - | G27: =_xlfn.XLOOKUP(F27, pin_name_table!$A$2:$A$171,pin_name_table!$B$2:$B$171,"") | H27: -
A28: 35 | B28: SPDIF RX | C28: 132 | D28: 35 / - / 132 / SPDIF_RX | E28: - | F28: - | G28: =_xlfn.XLOOKUP(F28, pin_name_table!$A$2:$A$171,pin_name_table!$B$2:$B$171,"") | H28: -
A29: 36 | B29: PDM D0 | C29: 99 | D29: 36 / - / - / PDM_D0 | E29: - | F29: PB_2 | G29: =_xlfn.XLOOKUP(F29, pin_name_table!$A$2:$A$171,pin_name_table!$B$2:$B$171,"") -> 32 | H29: 83
A30: 37 | B30: GPIO0 | C30: 160 | D30: 37 / - / 160 / GPIO0 | E30: - | F30: PC_13 | G30: =_xlfn.XLOOKUP(F30, pin_name_table!$A$2:$A$171,pin_name_table!$B$2:$B$171,"") -> 41 | H30: 27
A31: 38 | B31: PDM D1 | C31: 98 | D31: 38 / - / - / PDM_D1 | E31: - | F31: - | G31: =_xlfn.XLOOKUP(F31, pin_name_table!$A$2:$A$171,pin_name_table!$B$2:$B$171,"") | H31: -
A32: 39 | B32: GPIO1 | C32: 161 | D32: 39 / - / 161 / GPIO1 | E32: - | F32: PC_15 | G32: =_xlfn.XLOOKUP(F32, pin_name_table!$A$2:$A$171,pin_name_table!$B$2:$B$171,"") -> 42 | H32: 28
A33: 40 | B33: GPIO6 | C33: 166 | D33: 40 / - / 166 / GPIO6 | E33: - | F33: PG_10 | G33: =_xlfn.XLOOKUP(F33, pin_name_table!$A$2:$A$171,pin_name_table!$B$2:$B$171,"") -> 52 | H33: 33
A34: 41 | B34: GPIO2 | C34: 162 | D34: 41 / - / 162 / GPIO2 | E34: - | F34: PD_4 | G34: =_xlfn.XLOOKUP(F34, pin_name_table!$A$2:$A$171,pin_name_table!$B$2:$B$171,"") -> 44 | H34: 29
A35: 42 | B35: GPIO5 | C35: 165 | D35: 42 / - / 165 / GPIO5 | E35: - | F35: PG_3 | G35: =_xlfn.XLOOKUP(F35, pin_name_table!$A$2:$A$171,pin_name_table!$B$2:$B$171,"") -> 50 | H35: 32
A36: 43 | B36: GPIO3 | C36: 163 | D36: 43 / - / 163 / GPIO3 | E36: - | F36: PD_5 | G36: =_xlfn.XLOOKUP(F36, pin_name_table!$A$2:$A$171,pin_name_table!$B$2:$B$171,"") -> 45 | H36: 30
A37: 44 | B37: GPIO4 | C37: 164 | D37: 44 / - / 164 / GPIO4 | E37: - | F37: PE_3 | G37: =_xlfn.XLOOKUP(F37, pin_name_table!$A$2:$A$171,pin_name_table!$B$2:$B$171,"") -> 49 | H37: 31
G38: =_xlfn.XLOOKUP(F38, pin_name_table!$A$2:$A$171,pin_name_table!$B$2:$B$171,"")
G39: =_xlfn.XLOOKUP(F39, pin_name_table!$A$2:$A$171,pin_name_table!$B$2:$B$171,"")
A40: Breakout Header (J15) | G40: =_xlfn.XLOOKUP(F40, pin_name_table!$A$2:$A$171,pin_name_table!$B$2:$B$171,"")
A41: Pin_x000D_ number | B41: Function | C41: Portenta X8_x000D_ (Linux) | D41: Portenta X8_x000D_ (Python® - Modes:_x000D_ BOARD / BCM / IMX / X8) | E41: Portenta X8_x000D_ (Arduino) | F41: Portenta H7 | G41: =_xlfn.XLOOKUP(F41, pin_name_table!$A$2:$A$171,pin_name_table!$B$2:$B$171,"") | H41: Portenta C33
A42: 9 | B42: Analog 0 [A0] | C42: 167 | D42: 53 / - / 167 / A0 | E42: - | F42: PA_0C / A0 | G42: =_xlfn.XLOOKUP(F42, pin_name_table!$A$2:$A$171,pin_name_table!$B$2:$B$171,"") | H42: 15
A43: 10 | B43: SPI0 CS | C43: 141 | D43: 54 / - / 141 / SPI0_CS | E43: - | F43: - | G43: =_xlfn.XLOOKUP(F43, pin_name_table!$A$2:$A$171,pin_name_table!$B$2:$B$171,"") | H43: 7
A44: 11 | B44: Analog 1 [A1] | C44: 168 | D44: 55 / - / 168 / A1 | E44: - | F44: PA_1C / A1 | G44: =_xlfn.XLOOKUP(F44, pin_name_table!$A$2:$A$171,pin_name_table!$B$2:$B$171,"") | H44: 16
A45: 12 | B45: SPI0 SCLK | C45: 138 | D45: 56 / - / 138 / SPI0_SCLK | E45: - | F45: - | G45: =_xlfn.XLOOKUP(F45, pin_name_table!$A$2:$A$171,pin_name_table!$B$2:$B$171,"") | H45: 9
A46: 13 | B46: Analog 2 [A2[ | C46: 169 | D46: 57 / - / 169 / A2 | E46: - | F46: PC_2C / A2 | G46: =_xlfn.XLOOKUP(F46, pin_name_table!$A$2:$A$171,pin_name_table!$B$2:$B$171,"") | H46: 17
A47: 14 | B47: SPI0 CIPO | C47: 140 | D47: 58 / - / 140 / SPI0_CIPO | E47: PA_9 | F47: - | G47: =_xlfn.XLOOKUP(F47, pin_name_table!$A$2:$A$171,pin_name_table!$B$2:$B$171,"") | H47: 10
A48: 15 | B48: Analog 3 [A3[ | C48: 170 | D48: 59 / - / 170 / A3 | E48: - | F48: PC_3C / A3 | G48: =_xlfn.XLOOKUP(F48, pin_name_table!$A$2:$A$171,pin_name_table!$B$2:$B$171,"") | H48: 18
A49: 16 | B49: SPI0 COPI | C49: 139 | D49: 60 / - / 139 / SPI0_COPI | E49: - | F49: - | G49: =_xlfn.XLOOKUP(F49, pin_name_table!$A$2:$A$171,pin_name_table!$B$2:$B$171,"") | H49: 8
A50: 17 | B50: Analog 4 [A4] | C50: 171 | D50: 61 / - / 171 / A4 | E50: PA_10 | F50: PC_2 / A4 | G50: =_xlfn.XLOOKUP(F50, pin_name_table!$A$2:$A$171,pin_name_table!$B$2:$B$171,"") -> 0 | H50: 19
A51: 18 | B51: SPI1 CS | C51: 137 | D51: 62 / - / 137 / SPI1_CS | E51: - | F51: PI_0 | G51: =_xlfn.XLOOKUP(F51, pin_name_table!$A$2:$A$171,pin_name_table!$B$2:$B$171,"") -> 7 | H51: 48
...

Sheet Hat
A1: 40-Pins Connector Compatible With Raspberry Pi® HATs (J5)
A2: Pin_x000D_ number | B2: Function | C2: Portenta X8_x000D_ (Linux) | D2: Portenta X8_x000D_ (Python® - Modes:_x000D_ BOARD / BCM / IMX / X8) | E2: Portenta X8_x000D_ (Arduino) | F2: Portenta H7 | G2: Arduino H7 Pin | H2: Portenta C33
A3: 3 | B3: I2C2 SDA | C3: 149 | D3: 3 / 2 / 149 / I2C2_SDA | E3: - | F3: PH_12 | G3: =_xlfn.XLOOKUP(F3, pin_name_table!$A$2:$A$171,pin_name_table!$B$2:$B$171,"") -> 58 | H3: 39
A4: 5 | B4: I2C2 SCL | C4: 148 | D4: 5 / 3 / 148 / I2C2_SCL | E4: - | F4: PH_11 | G4: =_xlfn.XLOOKUP(F4, pin_name_table!$A$2:$A$171,pin_name_table!$B$2:$B$171,"") -> 57 | H4: 40
A5: 7 | B5: PWM0_x000D_ [1WIRE] | C5: 183 | D5: 7 / 4 / 183 / PWM0 | E5: PC_7 | F5: PA_8 | G5: =_xlfn.XLOOKUP(F5, pin_name_table!$A$2:$A$171,pin_name_table!$B$2:$B$171,"") -> 6 | H5: 0
A6: 8 | B6: SERIAL3 TX | C6: 157 | D6: 8 / 14 / 157 / TX3 | E6: - | F6: PJ_8 | G6: =_xlfn.XLOOKUP(F6, pin_name_table!$A$2:$A$171,pin_name_table!$B$2:$B$171,"") -> 75 | H6: 53
A7: 10 | B7: SERIAL3 RX | C7: 156 | D7: 10 / 15 / 156 / RX3 | E7: - | F7: PJ_9 | G7: =_xlfn.XLOOKUP(F7, pin_name_table!$A$2:$A$171,pin_name_table!$B$2:$B$171,"") -> 76 | H7: 54
A8: 11 | B8: GPIO2 | C8: 162 | D8: 11 / 17 / - / GPIO2 | E8: PF_3 | F8: PD_4 | G8: =_xlfn.XLOOKUP(F8, pin_name_table!$A$2:$A$171,pin_name_table!$B$2:$B$171,"") -> 44 | H8: 29
A9: 12 | B9: I2S CK_x000D_ [PCM_CLK] | C9: 87 | D9: 12 / 18 / 87 / I2S_CK | E9: - | F9: PD_3 | G9: =_xlfn.XLOOKUP(F9, pin_name_table!$A$2:$A$171,pin_name_table!$B$2:$B$171,"") -> 43 | H9: 63
A10: 13 | B10: GPIO6 | C10: 166 | D10: 13 / 27 / - / GPIO6 | E10: PE_11 | F10: PG_10 | G10: =_xlfn.XLOOKUP(F10, pin_name_table!$A$2:$A$171,pin_name_table!$B$2:$B$171,"") -> 52 | H10: 33
A11: 15 | B11: SAI D0_x000D_ (OUTPUT ONLY) | C11: 108 | D11: 15 / 22 / 108 / SAI_D0 | E11: - | F11: PI_6 | G11: =_xlfn.XLOOKUP(F11, pin_name_table!$A$2:$A$171,pin_name_table!$B$2:$B$171,"") | H11: 80
A12: 16 | B12: SAI CK_x000D_ (OUTPUT ONLY) | C12: 107 | D12: 16 / 23 / 107 / SAI_CK | E12: - | F12: PI_5 | G12: =_xlfn.XLOOKUP(F12, pin_name_table!$A$2:$A$171,pin_name_table!$B$2:$B$171,"") -> 64 | H12: 78
A13: 18 | B13: SAI FS_x000D_ (OUTPUT ONLY) | C13: 106 | D13: 18 / 24 / 106 / SAI_FS | E13: - | F13: PI_7 | G13: =_xlfn.XLOOKUP(F13, pin_name_table!$A$2:$A$171,pin_name_table!$B$2:$B$171,"") | H13: 79
A14: 19 | B14: SPI1 COPI_x000D_ (DTB Activated) | C14: 135 | D14: 19 / 10 / 135 / SPI1_COPI | E14: - | F14: PC_3 | G14: =_xlfn.XLOOKUP(F14, pin_name_table!$A$2:$A$171,pin_name_table!$B$2:$B$171,"") -> 8 | H14: 46
... A23: 31 | B23: PWM3 | C23: 186 | D23: 31 / 6 / 186 / PWM3 | E23: PB_10 | F23: PG_7 | G23: =_xlfn.XLOOKUP(F23, pin_name_table!$A$2:$A$171,pin_name_table!$B$2:$B$171,"") -> 3 | H23: 3
A24: 32 | B24: SERIAL1 TX | C24: 128 | D24: 31 / 12 / 128 / TX1 | E24: - | F24: PA_9 | G24: =_xlfn.XLOOKUP(F24, pin_name_table!$A$2:$A$171,pin_name_table!$B$2:$B$171,"") -> 14 | H24: 14
A25: 33 | B25: PWM4 | C25: 187 | D25: 33 / 13 / 187 / PWM4 | E25: PA_11 | F25: PJ_11 | G25: =_xlfn.XLOOKUP(F25, pin_name_table!$A$2:$A$171,pin_name_table!$B$2:$B$171,"") -> 2 | H25: 4
A26: 35 | B26: I2S WS | C26: 86 | D26: 35 / 19 / 86 / I2S_WS | E26: - | F26: PB_9 | G26: =_xlfn.XLOOKUP(F26, pin_name_table!$A$2:$A$171,pin_name_table!$B$2:$B$171,"") -> 38 | H26: 64
A27: 36 | B27: PWM5 | C27: 188 | D27: 36 / 16 / 188 / PWM5 | E27: PD_15 | F27: PK_1 | G27: =_xlfn.XLOOKUP(F27, pin_name_table!$A$2:$A$171,pin_name_table!$B$2:$B$171,"") -> 1 | H27: 5
A28: 37 | B28: PWM6 | C28: 189 | D28: 37 / 26 / 189 / PWM6 | E28: PA_8 | F28: PH_15 | G28: =_xlfn.XLOOKUP(F28, pin_name_table!$A$2:$A$171,pin_name_table!$B$2:$B$171,"") -> 0 | H28: 6
A29: 38 | B29: I2S SDI | C29: 85 | D29: 38 / 20 / 85 / I2S_SDI | E29: - | F29: PI_2 | G29: =_xlfn.XLOOKUP(F29, pin_name_table!$A$2:$A$171,pin_name_table!$B$2:$B$171,"") -> 61 | H29: 65
A30: 40 | B30: I2S SDO | C30: 88 | D30: 40 / 21 / 88 / I2S_SDO | E30: - | F30: PI_3 | G30: =_xlfn.XLOOKUP(F30, pin_name_table!$A$2:$A$171,pin_name_table!$B$2:$B$171,"") -> 62 | H30: 66
A32: Analog 16-Pin Header (J6)
A33: Pin_x000D_ number | B33: Function | C33: Portenta X8_x000D_ (Linux) | D33: Portenta X8_x000D_ (Arduino) | F33: Portenta H7 | H33: Portenta C33
A34: 1 | B34: A0 | C34: 167 | D34: A0 | F34: PA_0C / A0 | G34: =_xlfn.XLOOKUP(F34, pin_name_table!$A$2:$A$171,pin_name_table!$B$2:$B$171,"") | H34: 15
A35: 2 | B35: A1 | C35: 168 | D35: A1 | F35: PA_1C / A1 | G35: =_xlfn.XLOOKUP(F35, pin_name_table!$A$2:$A$171,pin_name_table!$B$2:$B$171,"") | H35: 16
A36: 3 | B36: A2 | C36: 169 | D36: A2 | F36: PC_2C / A2 | G36: =_xlfn.XLOOKUP(F36, pin_name_table!$A$2:$A$171,pin_name_table!$B$2:$B$171,"") | H36: 17
A37: 4 | B37: A3 | C37: 170 | D37: A3 | F37: PC_3C / A3 | G37: =_xlfn.XLOOKUP(F37, pin_name_table!$A$2:$A$171,pin_name_table!$B$2:$B$171,"") | H37: 18
A38: 5 | B38: A4 | C38: 171 | D38: A4 | F38: PC_2 / A4 | G38: =_xlfn.XLOOKUP(F38, pin_name_table!$A$2:$A$171,pin_name_table!$B$2:$B$171,"") -> 0 | H38: 19
A39: 6 | B39: A5 | C39: 172 | D39: A5 | F39: PC_3 / A5 | G39: =_xlfn.XLOOKUP(F39, pin_name_table!$A$2:$A$171,pin_name_table!$B$2:$B$171,"") -> 8 | H39: 20
A40: 7 | B40: A6 | C40: 173 | D40: A6 | F40: PA_4 / A6 | G40: =_xlfn.XLOOKUP(F40, pin_name_table!$A$2:$A$171,pin_name_table!$B$2:$B$171,"") -> 21 | H40: 21
A41: 8 | B41: A7 | C41: 174 | D41: A7 | F41: PA_6 / A7 | G41: =_xlfn.XLOOKUP(F41, pin_name_table!$A$2:$A$171,pin_name_table!$B$2:$B$171,"") -> 22 | H41: 22
A42: 9 | B42: PWM7 | C42: 190 | D42: PC_6 | F42: PJ_7 | G42: =_xlfn.XLOOKUP(F42, pin_name_table!$A$2:$A$171,pin_name_table!$B$2:$B$171,"") -> 74 | H42: 23
A43: 10 | B43: PWM8 | C43: 191 | D43: PA_12 | F43: PJ_10 | G43: =_xlfn.XLOOKUP(F43, pin_name_table!$A$2:$A$171,pin_name_table!$B$2:$B$171,"") -> 77 | H43: 24
A44: 12 | B44: GPIO0_x000D_ [PWM4 Silkscreen] | C44: 160 | D44: PF_8 | F44: PC_13 | G44: =_xlfn.XLOOKUP(F44, pin_name_table!$A$2:$A$171,pin_name_table!$B$2:$B$171,"") -> 41 | H44: 27
A45: 14 | B45: SERIAL2 TX | C45: 155 | D45: - | F45: PG_14 | G45: =_xlfn.XLOOKUP(F45, pin_name_table!$A$2:$A$171,pin_name_table!$B$2:$B$171,"") -> 53 | H45: 57
A46: 16 | B46: SERIAL2 RX | C46: 154 | D46: - | F46: PG_9 | G46: =_xlfn.XLOOKUP(F46, pin_name_table!$A$2:$A$171,pin_name_table!$B$2:$B$171,"") -> 51 | H46: 58
A48: On-Board Element
A49: Function | B49: Portenta X8_x000D_ (Linux) | D49: Portenta X8_x000D_ (Arduino) | F49: Portenta H7 | H49: Portenta C33
A50: GPIO3 (User LED) | B50: 163 | D50: PF_4 | F50: PD_5 | G50: =_xlfn.XLOOKUP(F50, pin_name_table!$A$2:$A$171,pin_name_table!$B$2:$B$171,"") -> 45 | H50: 30
...

Sheet pin_name_table
A1: Column1 | B1: Column2
A2: PA_0 | B2: 27
A3: PA_1
A4: PA_2
A5: PA_3
A6: PA_4 | B6: 21
A7: PA_4 / A6 | B7: 21
A8: PA_5
A9: PA_6 | B9: 22
A10: PA_6 / A7 | B10: 22
A11: PA_7
A12: PA_8 | B12: 6
A13: PA_9 | B13: 14
A14: PA_10 | B14: 13
A15: PA_11 | B15: 28
A16: PA_12 | B16: 29
A17: PA_13 | B17: 30
A18: PA_14 | B18: 31
A19: PA_15
A20: PB_0
A21: PB_1
A22: PB_2 | B22: 32
A23: PB_3 | B23: 33
A24: PB_4 | B24: 34
A25: PB_5
A26: PB_6 | B26: 35
A27: PB_7 | B27: 36
A28: PB_8 | B28: 37
A29: PB_9 | B29: 38
A30: PB_10
A31: PB_11
A32: PB_12
A33: PB_13
A34: PB_14 | B34: 39
A35: PB_15 | B35: 40
A36: PC_0
A37: PC_1
A38: PC_2 | B38: 10
A39: PC_2 / A4
A40: PC_3 | B40: 8
...
